Workbook
Name WeekEndDay: SETTINGS!$B$4
Name DefaultWindow: SETTINGS!$B$5
Name RAG_Green: SETTINGS!$B$6
Name RAG_Amber: SETTINGS!$B$7
Name UtilLow: SETTINGS!$B$8
Name UtilHigh: SETTINGS!$B$9
Name UtilLowWeeks: SETTINGS!$B$10
Name Cap_FT: SETTINGS!$B$11
Name Cap_Coaster: SETTINGS!$B$12
Name Cap_Electric: SETTINGS!$B$13
Name Cap_Big: SETTINGS!$B$14
Name CurrencySymbol: SETTINGS!$B$15
Name WSF_SelectList: OFFSET(CALC_SEARCH!$C$2,0,0,MAX(1,MIN(250,CALC_SEARCH!$D$2)),1)
Name WSF_WeekList: OFFSET(CALC_LISTS!$A$1,0,0,1+CALC_LISTS!$B$6,1)
Name TRANSPORT_SelectList: OFFSET(CALC_SEARCH!$H$2,0,0,MAX(1,MIN(250,CALC_SEARCH!$I$2)),1)
Name TRANSPORT_WeekList: OFFSET(CALC_LISTS!$C$1,0,0,1+CALC_LISTS!$D$6,1)

Sheet HOME
B1: OPERATIONS REPORTING & ANALYSIS | L1: ⌂ HOME
B2: Central · 92 Areas · Zones · Cells · Community Churches · Transport
B4: Dashboards
B6: MASTER DASHBOARD | F6: WSF DASHBOARD | J6: MIDWEEK DASHBOARD
B7: All streams side by side | F7: Saturday cell services | J7: Zonal midweek services
B10: CHOP DASHBOARD | F10: COMMUNITY CHURCH DASHBOARD | J10: TRANSPORT DASHBOARD
B11: Covenant Hour of Prayer | F11: Sunday service first | J11: Operations, finance, optimisation
B14: AREA SCORECARD | F14: ZONE SCORECARD | J14: DATA QUALITY
B15: One Area across every stream | F15: One Zone across every stream | J15: Rejected rows and missing weeks
B19: Data status
B20: Last data loaded | E20: =IF(MAX(DATA_WSF!$N:$N,DATA_MIDWEEK!$K:$K,DATA_CHOP!$K:$K,DATA_COMMUNITY!$K:$K,DATA_TRANSPORT!$AA:$AA,DATA_TRANSPORT_COSTS!$P:$P,DATA_TRANSPORT_BUDGET!$J:$J)=0,"No data yet",MAX(DATA_WSF!$N:$N,DATA_MIDWEEK!$K:$K,DATA_CHOP!$K:$K,DATA_COMMUNITY!$K:$K,DATA_TRANSPORT!$AA:$AA,DATA_TRANSPORT_COSTS!$P:$P,DATA_TRANSPORT_BUDGET!$J:$J)) | J20: How to use
J21: 1. Choose a dashboard above. Every dashboard has the same control strip at the top.
B22: Stream | E22: Latest week | G22: Rows in workbook | J22: 2. SCOPE: Global for everything, Area for one Area, Zone for one Zone.
B23: WSF | E23: =IF(MAX(DATA_WSF!$A:$A)=0,"–",MAX(DATA_WSF!$A:$A)) | G23: =COUNT(DATA_WSF!$A:$A) | J23: 3. SEARCH: type part of a name (e.g. 'ikeja'), then open SELECT: it lists only the matching Areas or Zones.
B24: Midweek | E24: =IF(MAX(DATA_MIDWEEK!$A:$A)=0,"–",MAX(DATA_MIDWEEK!$A:$A)) | G24: =COUNT(DATA_MIDWEEK!$A:$A) | J24: 4. WEEK ENDING: 'Latest' follows new data automatically; pick an older week to look back.
B25: CHOP | E25: =IF(MAX(DATA_CHOP!$A:$A)=0,"–",MAX(DATA_CHOP!$A:$A)) | G25: =COUNT(DATA_CHOP!$A:$A) | J25: 5. COMPARE (WEEKS): the averaging window, 1 to 52 weeks. '–' means there is no data for that figure.
B26: Community Church | E26: =IF(MAX(DATA_COMMUNITY!$A:$A)=0,"–",MAX(DATA_COMMUNITY!$A:$A)) | G26: =COUNT(DATA_COMMUNITY!$A:$A) | J26: 6. New data never goes into these sheets by hand: drop the files in the inbox folder and run ingest.py (see README).
B27: Transport bus runs | E27: =IF(MAX(DATA_TRANSPORT!$A:$A)=0,"–",MAX(DATA_TRANSPORT!$A:$A)) | G27: =COUNT(DATA_TRANSPORT!$A:$A)
B28: Transport coaster fuel | E28: =IF(MAX(DATA_TRANSPORT_COSTS!$A:$A)=0,"–",MAX(DATA_TRANSPORT_COSTS!$A:$A)) | G28: =COUNT(DATA_TRANSPORT_COSTS!$A:$A)
B29: Transport FT budget | E29: =IF(MAX(DATA_TRANSPORT_BUDGET!$A:$A)=0,"–",MAX(DATA_TRANSPORT_BUDGET!$A:$A)) | G29: =COUNT(DATA_TRANSPORT_BUDGET!$A:$A)
B30: Build in progress: the WSF and TRANSPORT dashboards, data tables, masters, Calendar, SETTINGS and DATA QUALITY are complete. Midweek, CHOP, Community, the scorecards and the Master dashboard follow as their sample files arrive.

Sheet MASTER DASHBOARD
B1: MASTER DASHBOARD | N1: ⌂ HOME
B2: Global view of every stream side by side
B4: Stage 2: this dashboard is built after the WSF DASHBOARD is reviewed, using the same control strip, KPI cards, time analysis, rankings and non-reporting layout. Its data is already loaded in the all DATA_* sheet.

Sheet WSF DASHBOARD
B1: WSF DASHBOARD | N1: ⌂ HOME
B2: Worship Service Fellowship · Saturday cell services · attendance and cell reporting compliance
B3: SCOPE | C3: SEARCH (type part of a name) | E3: SELECT AREA / ZONE ▼ | H3: STREAM | I3: WEEK ENDING ▼ | K3: COMPARE (WEEKS) | L3: SHOWING
B4: Global | H4: WSF | I4: Latest | K4: 4 | L4: =CALC_WSF!$B$16&IF(CALC_WSF!$B$10=0,""," · w/e "&TEXT(CALC_WSF!$B$10,"dd mmm yyyy"))&" · "&CALC_WSF!$B$11&"-wk window"
B5: =IF(CALC_WSF!$B$9=0,"No WSF data loaded yet. Put files in the inbox folder and run ingest.py.",IF(NOT(CALC_WSF!$B$5),"⚠ Pick "&IF(CALC_WSF!$B$3="Area","an Area","a Zone")&" from SELECT (type part of the name in SEARCH first to narrow the list).",IF(CALC_WSF!$Q$21=0,"No WSF reports in this scope for the selected week.","Numbers compare the selected week with the previous week and with the average of the "&CALC_WSF!$B$11&" weeks before it.")))
B7: GRAND TOTAL ATTENDANCE | D7: ADULTS (M + F) | F7: CHILDREN | H7: % CELLS REPORTING | J7: CELLS REPORTED | L7: AVG PER REPORTING CELL | N7: ZONES WITH NO CELL REPORT
B8: =IF(CALC_WSF!$B$90="","–",CALC_WSF!$B$90) | D8: =IF(CALC_WSF!$B$91="","–",CALC_WSF!$B$91) | F8: =IF(CALC_WSF!$B$94="","–",CALC_WSF!$B$94) | H8: =IF(CALC_WSF!$B$98="","–",CALC_WSF!$B$98) | J8: =IF(CALC_WSF!$B$96="","–",CALC_WSF!$B$96) | L8: =IF(CALC_WSF!$B$100="","–",CALC_WSF!$B$100) | N8: =IF(CALC_WSF!$Q$21=0,"–",CALC_WSF!$B$17)
B9: =IF(CALC_WSF!$E$90="","– vs prev wk",IF(CALC_WSF!$E$90>=0,"▲ ","▼ ")&TEXT(ABS(CALC_WSF!$E$90),"0.0%")&" vs prev wk") | D9: =IF(CALC_WSF!$E$91="","– vs prev wk",IF(CALC_WSF!$E$91>=0,"▲ ","▼ ")&TEXT(ABS(CALC_WSF!$E$91),"0.0%")&" vs prev wk") | F9: =IF(CALC_WSF!$E$94="","– vs prev wk",IF(CALC_WSF!$E$94>=0,"▲ ","▼ ")&TEXT(ABS(CALC_WSF!$E$94),"0.0%")&" vs prev wk") | H9: =IF(CALC_WSF!$D$98="","– vs prev wk",IF(CALC_WSF!$D$98>=0,"▲ ","▼ ")&TEXT(ABS(CALC_WSF!$D$98)*100,"0.0")&" pts vs prev wk") | J9: =IF(CALC_WSF!$E$96="","– vs prev wk",IF(CALC_WSF!$E$96>=0,"▲ ","▼ ")&TEXT(ABS(CALC_WSF!$E$96),"0.0%")&" vs prev wk") | L9: =IF(CALC_WSF!$E$100="","– vs prev wk",IF(CALC_WSF!$E$100>=0,"▲ ","▼ ")&TEXT(ABS(CALC_WSF!$E$100),"0.0%")&" vs prev wk") | N9: =IF(CALC_WSF!$Q$21=0,"","of "&TEXT(COUNTIFS(DATA_WSF!$A:$A,CALC_WSF!$B$10,DATA_WSF!$C:$C,CALC_WSF!$B$6,DATA_WSF!$D:$D,CALC_WSF!$B$7),"#,##0")&" zones")
B10: ="Avg last "&CALC_WSF!$B$11&" wks: "&IF(CALC_WSF!$F$90="","–",TEXT(CALC_WSF!$F$90,"#,##0")) | D10: ="Avg last "&CALC_WSF!$B$11&" wks: "&IF(CALC_WSF!$F$91="","–",TEXT(CALC_WSF!$F$91,"#,##0")) | F10: ="Avg last "&CALC_WSF!$B$11&" wks: "&IF(CALC_WSF!$F$94="","–",TEXT(CALC_WSF!$F$94,"#,##0")) | H10: ="Avg last "&CALC_WSF!$B$11&" wks: "&IF(CALC_WSF!$F$98="","–",TEXT(CALC_WSF!$F$98,"0.0%")) | J10: ="Avg last "&CALC_WSF!$B$11&" wks: "&IF(CALC_WSF!$F$96="","–",TEXT(CALC_WSF!$F$96,"#,##0")) | L10: ="Avg last "&CALC_WSF!$B$11&" wks: "&IF(CALC_WSF!$F$100="","–",TEXT(CALC_WSF!$F$100,"#,##0.0")) | N10: ="Zones where not one cell reported"
B12: Time analysis — selected week against previous week, the N-week average and period-to-date
B13: KPI | D13: Selected week | E13: Previous week | F13: Change | G13: % change | H13: ="Avg last "&CALC_WSF!$B$11&" wks" | I13: ="vs "&CALC_WSF!$B$11&"-wk avg" | J13: MTD total | K13: QTD total | L13: YTD total | M13: Wkly avg (month) | N13: Wkly avg (qtr) | O13: Wkly avg (year)
B14: Grand total attendance | D14: =IF(CALC_WSF!$B$90="","–",CALC_WSF!$B$90) | E14: =IF(CALC_WSF!$C$90="","–",CALC_WSF!$C$90) | F14: =IF(CALC_WSF!$D$90="","–",CALC_WSF!$D$90) | G14: =IF(CALC_WSF!$E$90="","–",CALC_WSF!$E$90) | H14: =IF(CALC_WSF!$F$90="","–",CALC_WSF!$F$90) | I14: =IF(CALC_WSF!$G$90="","–",CALC_WSF!$G$90) | J14: =IF(CALC_WSF!$H$90="","–",CALC_WSF!$H$90) | K14: =IF(CALC_WSF!$I$90="","–",CALC_WSF!$I$90) | L14: =IF(CALC_WSF!$J$90="","–",CALC_WSF!$J$90) | M14: =IF(CALC_WSF!$K$90="","–",CALC_WSF!$K$90) | N14: =IF(CALC_WSF!$L$90="","–",CALC_WSF!$L$90) | O14: =IF(CALC_WSF!$M$90="","–",CALC_WSF!$M$90)
B15: Adult total (Male + Female) | D15: =IF(CALC_WSF!$B$91="","–",CALC_WSF!$B$91) | E15: =IF(CALC_WSF!$C$91="","–",CALC_WSF!$C$91) | F15: =IF(CALC_WSF!$D$91="","–",CALC_WSF!$D$91) | G15: =IF(CALC_WSF!$E$91="","–",CALC_WSF!$E$91) | H15: =IF(CALC_WSF!$F$91="","–",CALC_WSF!$F$91) | I15: =IF(CALC_WSF!$G$91="","–",CALC_WSF!$G$91) | J15: =IF(CALC_WSF!$H$91="","–",CALC_WSF!$H$91) | K15: =IF(CALC_WSF!$I$91="","–",CALC_WSF!$I$91) | L15: =IF(CALC_WSF!$J$91="","–",CALC_WSF!$J$91) | M15: =IF(CALC_WSF!$K$91="","–",CALC_WSF!$K$91) | N15: =IF(CALC_WSF!$L$91="","–",CALC_WSF!$L$91) | O15: =IF(CALC_WSF!$M$91="","–",CALC_WSF!$M$91)
B16: Male | D16: =IF(CALC_WSF!$B$92="","–",CALC_WSF!$B$92) | E16: =IF(CALC_WSF!$C$92="","–",CALC_WSF!$C$92) | F16: =IF(CALC_WSF!$D$92="","–",CALC_WSF!$D$92) | G16: =IF(CALC_WSF!$E$92="","–",CALC_WSF!$E$92) | H16: =IF(CALC_WSF!$F$92="","–",CALC_WSF!$F$92) | I16: =IF(CALC_WSF!$G$92="","–",CALC_WSF!$G$92) | J16: =IF(CALC_WSF!$H$92="","–",CALC_WSF!$H$92) | K16: =IF(CALC_WSF!$I$92="","–",CALC_WSF!$I$92) | L16: =IF(CALC_WSF!$J$92="","–",CALC_WSF!$J$92) | M16: =IF(CALC_WSF!$K$92="","–",CALC_WSF!$K$92) | N16: =IF(CALC_WSF!$L$92="","–",CALC_WSF!$L$92) | O16: =IF(CALC_WSF!$M$92="","–",CALC_WSF!$M$92)
B17: Female | D17: =IF(CALC_WSF!$B$93="","–",CALC_WSF!$B$93) | E17: =IF(CALC_WSF!$C$93="","–",CALC_WSF!$C$93) | F17: =IF(CALC_WSF!$D$93="","–",CALC_WSF!$D$93) | G17: =IF(CALC_WSF!$E$93="","–",CALC_WSF!$E$93) | H17: =IF(CALC_WSF!$F$93="","–",CALC_WSF!$F$93) | I17: =IF(CALC_WSF!$G$93="","–",CALC_WSF!$G$93) | J17: =IF(CALC_WSF!$H$93="","–",CALC_WSF!$H$93) | K17: =IF(CALC_WSF!$I$93="","–",CALC_WSF!$I$93) | L17: =IF(CALC_WSF!$J$93="","–",CALC_WSF!$J$93) | M17: =IF(CALC_WSF!$K$93="","–",CALC_WSF!$K$93) | N17: =IF(CALC_WSF!$L$93="","–",CALC_WSF!$L$93) | O17: =IF(CALC_WSF!$M$93="","–",CALC_WSF!$M$93)
B18: Children | D18: =IF(CALC_WSF!$B$94="","–",CALC_WSF!$B$94) | E18: =IF(CALC_WSF!$C$94="","–",CALC_WSF!$C$94) | F18: =IF(CALC_WSF!$D$94="","–",CALC_WSF!$D$94) | G18: =IF(CALC_WSF!$E$94="","–",CALC_WSF!$E$94) | H18: =IF(CALC_WSF!$F$94="","–",CALC_WSF!$F$94) | I18: =IF(CALC_WSF!$G$94="","–",CALC_WSF!$G$94) | J18: =IF(CALC_WSF!$H$94="","–",CALC_WSF!$H$94) | K18: =IF(CALC_WSF!$I$94="","–",CALC_WSF!$I$94) | L18: =IF(CALC_WSF!$J$94="","–",CALC_WSF!$J$94) | M18: =IF(CALC_WSF!$K$94="","–",CALC_WSF!$K$94) | N18: =IF(CALC_WSF!$L$94="","–",CALC_WSF!$L$94) | O18: =IF(CALC_WSF!$M$94="","–",CALC_WSF!$M$94)
B19: Operational cells | D19: =IF(CALC_WSF!$B$95="","–",CALC_WSF!$B$95) | E19: =IF(CALC_WSF!$C$95="","–",CALC_WSF!$C$95) | F19: =IF(CALC_WSF!$D$95="","–",CALC_WSF!$D$95) | G19: =IF(CALC_WSF!$E$95="","–",CALC_WSF!$E$95) | H19: =IF(CALC_WSF!$F$95="","–",CALC_WSF!$F$95) | I19: =IF(CALC_WSF!$G$95="","–",CALC_WSF!$G$95) | J19: =IF(CALC_WSF!$H$95="","–",CALC_WSF!$H$95) | K19: =IF(CALC_WSF!$I$95="","–",CALC_WSF!$I$95) | L19: =IF(CALC_WSF!$J$95="","–",CALC_WSF!$J$95) | M19: =IF(CALC_WSF!$K$95="","–",CALC_WSF!$K$95) | N19: =IF(CALC_WSF!$L$95="","–",CALC_WSF!$L$95) | O19: =IF(CALC_WSF!$M$95="","–",CALC_WSF!$M$95)
B20: Cells that reported | D20: =IF(CALC_WSF!$B$96="","–",CALC_WSF!$B$96) | E20: =IF(CALC_WSF!$C$96="","–",CALC_WSF!$C$96) | F20: =IF(CALC_WSF!$D$96="","–",CALC_WSF!$D$96) | G20: =IF(CALC_WSF!$E$96="","–",CALC_WSF!$E$96) | H20: =IF(CALC_WSF!$F$96="","–",CALC_WSF!$F$96) | I20: =IF(CALC_WSF!$G$96="","–",CALC_WSF!$G$96) | J20: =IF(CALC_WSF!$H$96="","–",CALC_WSF!$H$96) | K20: =IF(CALC_WSF!$I$96="","–",CALC_WSF!$I$96) | L20: =IF(CALC_WSF!$J$96="","–",CALC_WSF!$J$96) | M20: =IF(CALC_WSF!$K$96="","–",CALC_WSF!$K$96) | N20: =IF(CALC_WSF!$L$96="","–",CALC_WSF!$L$96) | O20: =IF(CALC_WSF!$M$96="","–",CALC_WSF!$M$96)
B21: Cells with no report | D21: =IF(CALC_WSF!$B$97="","–",CALC_WSF!$B$97) | E21: =IF(CALC_WSF!$C$97="","–",CALC_WSF!$C$97) | F21: =IF(CALC_WSF!$D$97="","–",CALC_WSF!$D$97) | G21: =IF(CALC_WSF!$E$97="","–",CALC_WSF!$E$97) | H21: =IF(CALC_WSF!$F$97="","–",CALC_WSF!$F$97) | I21: =IF(CALC_WSF!$G$97="","–",CALC_WSF!$G$97) | J21: =IF(CALC_WSF!$H$97="","–",CALC_WSF!$H$97) | K21: =IF(CALC_WSF!$I$97="","–",CALC_WSF!$I$97) | L21: =IF(CALC_WSF!$J$97="","–",CALC_WSF!$J$97) | M21: =IF(CALC_WSF!$K$97="","–",CALC_WSF!$K$97) | N21: =IF(CALC_WSF!$L$97="","–",CALC_WSF!$L$97) | O21: =IF(CALC_WSF!$M$97="","–",CALC_WSF!$M$97)
B22: % cells reporting | D22: =IF(CALC_WSF!$B$98="","–",CALC_WSF!$B$98) | E22: =IF(CALC_WSF!$C$98="","–",CALC_WSF!$C$98) | F22: =IF(CALC_WSF!$D$98="","–",CALC_WSF!$D$98*100) | G22: =IF(CALC_WSF!$E$98="","–",CALC_WSF!$E$98) | H22: =IF(CALC_WSF!$F$98="","–",CALC_WSF!$F$98) | I22: =IF(CALC_WSF!$G$98="","–",CALC_WSF!$G$98) | J22: =IF(CALC_WSF!$H$98="","–",CALC_WSF!$H$98) | K22: =IF(CALC_WSF!$I$98="","–",CALC_WSF!$I$98) | L22: =IF(CALC_WSF!$J$98="","–",CALC_WSF!$J$98) | M22: =IF(CALC_WSF!$K$98="","–",CALC_WSF!$K$98) | N22: =IF(CALC_WSF!$L$98="","–",CALC_WSF!$L$98) | O22: =IF(CALC_WSF!$M$98="","–",CALC_WSF!$M$98)
B23: Reporting : non-reporting | D23: =IF(CALC_WSF!$B$99="","–",CALC_WSF!$B$99) | E23: =IF(CALC_WSF!$C$99="","–",CALC_WSF!$C$99) | F23: =IF(CALC_WSF!$D$99="","–",CALC_WSF!$D$99) | G23: =IF(CALC_WSF!$E$99="","–",CALC_WSF!$E$99) | H23: =IF(CALC_WSF!$F$99="","–",CALC_WSF!$F$99) | I23: =IF(CALC_WSF!$G$99="","–",CALC_WSF!$G$99) | J23: =IF(CALC_WSF!$H$99="","–",CALC_WSF!$H$99) | K23: =IF(CALC_WSF!$I$99="","–",CALC_WSF!$I$99) | L23: =IF(CALC_WSF!$J$99="","–",CALC_WSF!$J$99) | M23: =IF(CALC_WSF!$K$99="","–",CALC_WSF!$K$99) | N23: =IF(CALC_WSF!$L$99="","–",CALC_WSF!$L$99) | O23: =IF(CALC_WSF!$M$99="","–",CALC_WSF!$M$99)
B24: Avg attendance per reporting cell | D24: =IF(CALC_WSF!$B$100="","–",CALC_WSF!$B$100) | E24: =IF(CALC_WSF!$C$100="","–",CALC_WSF!$C$100) | F24: =IF(CALC_WSF!$D$100="","–",CALC_WSF!$D$100) | G24: =IF(CALC_WSF!$E$100="","–",CALC_WSF!$E$100) | H24: =IF(CALC_WSF!$F$100="","–",CALC_WSF!$F$100) | I24: =IF(CALC_WSF!$G$100="","–",CALC_WSF!$G$100) | J24: =IF(CALC_WSF!$H$100="","–",CALC_WSF!$H$100) | K24: =IF(CALC_WSF!$I$100="","–",CALC_WSF!$I$100) | L24: =IF(CALC_WSF!$J$100="","–",CALC_WSF!$J$100) | M24: =IF(CALC_WSF!$K$100="","–",CALC_WSF!$K$100) | N24: =IF(CALC_WSF!$L$100="","–",CALC_WSF!$L$100) | O24: =IF(CALC_WSF!$M$100="","–",CALC_WSF!$M$100)
B25: Averages use only weeks that have data. MTD/QTD/YTD run to the selected week; for ratio rows the period columns show the ratio of the period's totals. Cell counts in period columns are cell-weeks.
B27: Trends
B44: Area rankings — selected week | O44: Growth = selected week vs previous week
B45: Top 10 · attendance | D45: Bottom 10 · attendance | F45: Top 10 · % reporting | H45: Bottom 10 · % reporting | J45: Top 10 · growth | L45: Bottom 10 · growth | N45: Selected Area rank
B46: =IF(CALC_WSF!$B$3="Zone","n/a at Zone scope",IF(CALC_WSF!$AJ$3="","–",1&". "&CALC_WSF!$AJ$3)) | C46: =IF(OR(CALC_WSF!$B$3="Zone",CALC_WSF!$AJ$3=""),"",CALC_WSF!$AK$3) | D46: =IF(CALC_WSF!$B$3="Zone","n/a at Zone scope",IF(CALC_WSF!$AL$3="","–",1&". "&CALC_WSF!$AL$3)) | E46: =IF(OR(CALC_WSF!$B$3="Zone",CALC_WSF!$AL$3=""),"",CALC_WSF!$AM$3) | F46: =IF(CALC_WSF!$B$3="Zone","n/a at Zone scope",IF(CALC_WSF!$AN$3="","–",1&". "&CALC_WSF!$AN$3)) | G46: =IF(OR(CALC_WSF!$B$3="Zone",CALC_WSF!$AN$3=""),"",CALC_WSF!$AO$3) | H46: =IF(CALC_WSF!$B$3="Zone","n/a at Zone scope",IF(CALC_WSF!$AP$3="","–",1&". "&CALC_WSF!$AP$3)) | I46: =IF(OR(CALC_WSF!$B$3="Zone",CALC_WSF!$AP$3=""),"",CALC_WSF!$AQ$3) | J46: =IF(CALC_WSF!$B$3="Zone","n/a at Zone scope",IF(CALC_WSF!$AR$3="","–",1&". "&CALC_WSF!$AR$3)) | K46: =IF(OR(CALC_WSF!$B$3="Zone",CALC_WSF!$AR$3=""),"",CALC_WSF!$AS$3) | L46: =IF(CALC_WSF!$B$3="Zone","n/a at Zone scope",IF(CALC_WSF!$AT$3="","–",1&". "&CALC_WSF!$AT$3)) | M46: =IF(OR(CALC_WSF!$B$3="Zone",CALC_WSF!$AT$3=""),"",CALC_WSF!$AU$3) | N46: Attendance | O46: =IF(CALC_WSF!$B$3<>"Area","n/a",IF(CALC_WSF!$AJ$15="","–",CALC_WSF!$AJ$15&" of "&CALC_WSF!$AJ$18))
B47: =IF(CALC_WSF!$B$3="Zone","",IF(CALC_WSF!$AJ$4="","",2&". "&CALC_WSF!$AJ$4)) | C47: =IF(OR(CALC_WSF!$B$3="Zone",CALC_WSF!$AJ$4=""),"",CALC_WSF!$AK$4) | D47: =IF(CALC_WSF!$B$3="Zone","",IF(CALC_WSF!$AL$4="","",2&". "&CALC_WSF!$AL$4)) | E47: =IF(OR(CALC_WSF!$B$3="Zone",CALC_WSF!$AL$4=""),"",CALC_WSF!$AM$4) | F47: =IF(CALC_WSF!$B$3="Zone","",IF(CALC_WSF!$AN$4="","",2&". "&CALC_WSF!$AN$4)) | G47: =IF(OR(CALC_WSF!$B$3="Zone",CALC_WSF!$AN$4=""),"",CALC_WSF!$AO$4) | H47: =IF(CALC_WSF!$B$3="Zone","",IF(CALC_WSF!$AP$4="","",2&". "&CALC_WSF!$AP$4)) | I47: =IF(OR(CALC_WSF!$B$3="Zone",CALC_WSF!$AP$4=""),"",CALC_WSF!$AQ$4) | J47: =IF(CALC_WSF!$B$3="Zone","",IF(CALC_WSF!$AR$4="","",2&". "&CALC_WSF!$AR$4)) | K47: =IF(OR(CALC_WSF!$B$3="Zone",CALC_WSF!$AR$4=""),"",CALC_WSF!$AS$4) | L47: =IF(CALC_WSF!$B$3="Zone","",IF(CALC_WSF!$AT$4="","",2&". "&CALC_WSF!$AT$4)) | M47: =IF(OR(CALC_WSF!$B$3="Zone",CALC_WSF!$AT$4=""),"",CALC_WSF!$AU$4) | N47: % reporting | O47: =IF(CALC_WSF!$B$3<>"Area","n/a",IF(CALC_WSF!$AJ$16="","–",CALC_WSF!$AJ$16&" of "&CALC_WSF!$AJ$18))
B48: =IF(CALC_WSF!$B$3="Zone","",IF(CALC_WSF!$AJ$5="","",3&". "&CALC_WSF!$AJ$5)) | C48: =IF(OR(CALC_WSF!$B$3="Zone",CALC_WSF!$AJ$5=""),"",CALC_WSF!$AK$5) | D48: =IF(CALC_WSF!$B$3="Zone","",IF(CALC_WSF!$AL$5="","",3&". "&CALC_WSF!$AL$5)) | E48: =IF(OR(CALC_WSF!$B$3="Zone",CALC_WSF!$AL$5=""),"",CALC_WSF!$AM$5) | F48: =IF(CALC_WSF!$B$3="Zone","",IF(CALC_WSF!$AN$5="","",3&". "&CALC_WSF!$AN$5)) | G48: =IF(OR(CALC_WSF!$B$3="Zone",CALC_WSF!$AN$5=""),"",CALC_WSF!$AO$5) | H48: =IF(CALC_WSF!$B$3="Zone","",IF(CALC_WSF!$AP$5="","",3&". "&CALC_WSF!$AP$5)) | I48: =IF(OR(CALC_WSF!$B$3="Zone",CALC_WSF!$AP$5=""),"",CALC_WSF!$AQ$5) | J48: =IF(CALC_WSF!$B$3="Zone","",IF(CALC_WSF!$AR$5="","",3&". "&CALC_WSF!$AR$5)) | K48: =IF(OR(CALC_WSF!$B$3="Zone",CALC_WSF!$AR$5=""),"",CALC_WSF!$AS$5) | L48: =IF(CALC_WSF!$B$3="Zone","",IF(CALC_WSF!$AT$5="","",3&". "&CALC_WSF!$AT$5)) | M48: =IF(OR(CALC_WSF!$B$3="Zone",CALC_WSF!$AT$5=""),"",CALC_WSF!$AU$5) | N48: Growth | O48: =IF(CALC_WSF!$B$3<>"Area","n/a",IF(CALC_WSF!$AJ$17="","–",CALC_WSF!$AJ$17&" of "&CALC_WSF!$AJ$18))
B49: =IF(CALC_WSF!$B$3="Zone","",IF(CALC_WSF!$AJ$6="","",4&". "&CALC_WSF!$AJ$6)) | C49: =IF(OR(CALC_WSF!$B$3="Zone",CALC_WSF!$AJ$6=""),"",CALC_WSF!$AK$6) | D49: =IF(CALC_WSF!$B$3="Zone","",IF(CALC_WSF!$AL$6="","",4&". "&CALC_WSF!$AL$6)) | E49: =IF(OR(CALC_WSF!$B$3="Zone",CALC_WSF!$AL$6=""),"",CALC_WSF!$AM$6) | F49: =IF(CALC_WSF!$B$3="Zone","",IF(CALC_WSF!$AN$6="","",4&". "&CALC_WSF!$AN$6)) | G49: =IF(OR(CALC_WSF!$B$3="Zone",CALC_WSF!$AN$6=""),"",CALC_WSF!$AO$6) | H49: =IF(CALC_WSF!$B$3="Zone","",IF(CALC_WSF!$AP$6="","",4&". "&CALC_WSF!$AP$6)) | I49: =IF(OR(CALC_WSF!$B$3="Zone",CALC_WSF!$AP$6=""),"",CALC_WSF!$AQ$6) | J49: =IF(CALC_WSF!$B$3="Zone","",IF(CALC_WSF!$AR$6="","",4&". "&CALC_WSF!$AR$6)) | K49: =IF(OR(CALC_WSF!$B$3="Zone",CALC_WSF!$AR$6=""),"",CALC_WSF!$AS$6) | L49: =IF(CALC_WSF!$B$3="Zone","",IF(CALC_WSF!$AT$6="","",4&". "&CALC_WSF!$AT$6)) | M49: =IF(OR(CALC_WSF!$B$3="Zone",CALC_WSF!$AT$6=""),"",CALC_WSF!$AU$6)
B50: =IF(CALC_WSF!$B$3="Zone","",IF(CALC_WSF!$AJ$7="","",5&". "&CALC_WSF!$AJ$7)) | C50: =IF(OR(CALC_WSF!$B$3="Zone",CALC_WSF!$AJ$7=""),"",CALC_WSF!$AK$7) | D50: =IF(CALC_WSF!$B$3="Zone","",IF(CALC_WSF!$AL$7="","",5&". "&CALC_WSF!$AL$7)) | E50: =IF(OR(CALC_WSF!$B$3="Zone",CALC_WSF!$AL$7=""),"",CALC_WSF!$AM$7) | F50: =IF(CALC_WSF!$B$3="Zone","",IF(CALC_WSF!$AN$7="","",5&". "&CALC_WSF!$AN$7)) | G50: =IF(OR(CALC_WSF!$B$3="Zone",CALC_WSF!$AN$7=""),"",CALC_WSF!$AO$7) | H50: =IF(CALC_WSF!$B$3="Zone","",IF(CALC_WSF!$AP$7="","",5&". "&CALC_WSF!$AP$7)) | I50: =IF(OR(CALC_WSF!$B$3="Zone",CALC_WSF!$AP$7=""),"",CALC_WSF!$AQ$7) | J50: =IF(CALC_WSF!$B$3="Zone","",IF(CALC_WSF!$AR$7="","",5&". "&CALC_WSF!$AR$7)) | K50: =IF(OR(CALC_WSF!$B$3="Zone",CALC_WSF!$AR$7=""),"",CALC_WSF!$AS$7) | L50: =IF(CALC_WSF!$B$3="Zone","",IF(CALC_WSF!$AT$7="","",5&". "&CALC_WSF!$AT$7)) | M50: =IF(OR(CALC_WSF!$B$3="Zone",CALC_WSF!$AT$7=""),"",CALC_WSF!$AU$7) | N50: Shown when Scope = Area. Rank 1 = highest.
B51: =IF(CALC_WSF!$B$3="Zone","",IF(CALC_WSF!$AJ$8="","",6&". "&CALC_WSF!$AJ$8)) | C51: =IF(OR(CALC_WSF!$B$3="Zone",CALC_WSF!$AJ$8=""),"",CALC_WSF!$AK$8) | D51: =IF(CALC_WSF!$B$3="Zone","",IF(CALC_WSF!$AL$8="","",6&". "&CALC_WSF!$AL$8)) | E51: =IF(OR(CALC_WSF!$B$3="Zone",CALC_WSF!$AL$8=""),"",CALC_WSF!$AM$8) | F51: =IF(CALC_WSF!$B$3="Zone","",IF(CALC_WSF!$AN$8="","",6&". "&CALC_WSF!$AN$8)) | G51: =IF(OR(CALC_WSF!$B$3="Zone",CALC_WSF!$AN$8=""),"",CALC_WSF!$AO$8) | H51: =IF(CALC_WSF!$B$3="Zone","",IF(CALC_WSF!$AP$8="","",6&". "&CALC_WSF!$AP$8)) | I51: =IF(OR(CALC_WSF!$B$3="Zone",CALC_WSF!$AP$8=""),"",CALC_WSF!$AQ$8) | J51: =IF(CALC_WSF!$B$3="Zone","",IF(CALC_WSF!$AR$8="","",6&". "&CALC_WSF!$AR$8)) | K51: =IF(OR(CALC_WSF!$B$3="Zone",CALC_WSF!$AR$8=""),"",CALC_WSF!$AS$8) | L51: =IF(CALC_WSF!$B$3="Zone","",IF(CALC_WSF!$AT$8="","",6&". "&CALC_WSF!$AT$8)) | M51: =IF(OR(CALC_WSF!$B$3="Zone",CALC_WSF!$AT$8=""),"",CALC_WSF!$AU$8)
B52: =IF(CALC_WSF!$B$3="Zone","",IF(CALC_WSF!$AJ$9="","",7&". "&CALC_WSF!$AJ$9)) | C52: =IF(OR(CALC_WSF!$B$3="Zone",CALC_WSF!$AJ$9=""),"",CALC_WSF!$AK$9) | D52: =IF(CALC_WSF!$B$3="Zone","",IF(CALC_WSF!$AL$9="","",7&". "&CALC_WSF!$AL$9)) | E52: =IF(OR(CALC_WSF!$B$3="Zone",CALC_WSF!$AL$9=""),"",CALC_WSF!$AM$9) | F52: =IF(CALC_WSF!$B$3="Zone","",IF(CALC_WSF!$AN$9="","",7&". "&CALC_WSF!$AN$9)) | G52: =IF(OR(CALC_WSF!$B$3="Zone",CALC_WSF!$AN$9=""),"",CALC_WSF!$AO$9) | H52: =IF(CALC_WSF!$B$3="Zone","",IF(CALC_WSF!$AP$9="","",7&". "&CALC_WSF!$AP$9)) | I52: =IF(OR(CALC_WSF!$B$3="Zone",CALC_WSF!$AP$9=""),"",CALC_WSF!$AQ$9) | J52: =IF(CALC_WSF!$B$3="Zone","",IF(CALC_WSF!$AR$9="","",7&". "&CALC_WSF!$AR$9)) | K52: =IF(OR(CALC_WSF!$B$3="Zone",CALC_WSF!$AR$9=""),"",CALC_WSF!$AS$9) | L52: =IF(CALC_WSF!$B$3="Zone","",IF(CALC_WSF!$AT$9="","",7&". "&CALC_WSF!$AT$9)) | M52: =IF(OR(CALC_WSF!$B$3="Zone",CALC_WSF!$AT$9=""),"",CALC_WSF!$AU$9)
B53: =IF(CALC_WSF!$B$3="Zone","",IF(CALC_WSF!$AJ$10="","",8&". "&CALC_WSF!$AJ$10)) | C53: =IF(OR(CALC_WSF!$B$3="Zone",CALC_WSF!$AJ$10=""),"",CALC_WSF!$AK$10) | D53: =IF(CALC_WSF!$B$3="Zone","",IF(CALC_WSF!$AL$10="","",8&". "&CALC_WSF!$AL$10)) | E53: =IF(OR(CALC_WSF!$B$3="Zone",CALC_WSF!$AL$10=""),"",CALC_WSF!$AM$10) | F53: =IF(CALC_WSF!$B$3="Zone","",IF(CALC_WSF!$AN$10="","",8&". "&CALC_WSF!$AN$10)) | G53: =IF(OR(CALC_WSF!$B$3="Zone",CALC_WSF!$AN$10=""),"",CALC_WSF!$AO$10) | H53: =IF(CALC_WSF!$B$3="Zone","",IF(CALC_WSF!$AP$10="","",8&". "&CALC_WSF!$AP$10)) | I53: =IF(OR(CALC_WSF!$B$3="Zone",CALC_WSF!$AP$10=""),"",CALC_WSF!$AQ$10) | J53: =IF(CALC_WSF!$B$3="Zone","",IF(CALC_WSF!$AR$10="","",8&". "&CALC_WSF!$AR$10)) | K53: =IF(OR(CALC_WSF!$B$3="Zone",CALC_WSF!$AR$10=""),"",CALC_WSF!$AS$10) | L53: =IF(CALC_WSF!$B$3="Zone","",IF(CALC_WSF!$AT$10="","",8&". "&CALC_WSF!$AT$10)) | M53: =IF(OR(CALC_WSF!$B$3="Zone",CALC_WSF!$AT$10=""),"",CALC_WSF!$AU$10)
B54: =IF(CALC_WSF!$B$3="Zone","",IF(CALC_WSF!$AJ$11="","",9&". "&CALC_WSF!$AJ$11)) | C54: =IF(OR(CALC_WSF!$B$3="Zone",CALC_WSF!$AJ$11=""),"",CALC_WSF!$AK$11) | D54: =IF(CALC_WSF!$B$3="Zone","",IF(CALC_WSF!$AL$11="","",9&". "&CALC_WSF!$AL$11)) | E54: =IF(OR(CALC_WSF!$B$3="Zone",CALC_WSF!$AL$11=""),"",CALC_WSF!$AM$11) | F54: =IF(CALC_WSF!$B$3="Zone","",IF(CALC_WSF!$AN$11="","",9&". "&CALC_WSF!$AN$11)) | G54: =IF(OR(CALC_WSF!$B$3="Zone",CALC_WSF!$AN$11=""),"",CALC_WSF!$AO$11) | H54: =IF(CALC_WSF!$B$3="Zone","",IF(CALC_WSF!$AP$11="","",9&". "&CALC_WSF!$AP$11)) | I54: =IF(OR(CALC_WSF!$B$3="Zone",CALC_WSF!$AP$11=""),"",CALC_WSF!$AQ$11) | J54: =IF(CALC_WSF!$B$3="Zone","",IF(CALC_WSF!$AR$11="","",9&". "&CALC_WSF!$AR$11)) | K54: =IF(OR(CALC_WSF!$B$3="Zone",CALC_WSF!$AR$11=""),"",CALC_WSF!$AS$11) | L54: =IF(CALC_WSF!$B$3="Zone","",IF(CALC_WSF!$AT$11="","",9&". "&CALC_WSF!$AT$11)) | M54: =IF(OR(CALC_WSF!$B$3="Zone",CALC_WSF!$AT$11=""),"",CALC_WSF!$AU$11)
B55: =IF(CALC_WSF!$B$3="Zone","",IF(CALC_WSF!$AJ$12="","",10&". "&CALC_WSF!$AJ$12)) | C55: =IF(OR(CALC_WSF!$B$3="Zone",CALC_WSF!$AJ$12=""),"",CALC_WSF!$AK$12) | D55: =IF(CALC_WSF!$B$3="Zone","",IF(CALC_WSF!$AL$12="","",10&". "&CALC_WSF!$AL$12)) | E55: =IF(OR(CALC_WSF!$B$3="Zone",CALC_WSF!$AL$12=""),"",CALC_WSF!$AM$12) | F55: =IF(CALC_WSF!$B$3="Zone","",IF(CALC_WSF!$AN$12="","",10&". "&CALC_WSF!$AN$12)) | G55: =IF(OR(CALC_WSF!$B$3="Zone",CALC_WSF!$AN$12=""),"",CALC_WSF!$AO$12) | H55: =IF(CALC_WSF!$B$3="Zone","",IF(CALC_WSF!$AP$12="","",10&". "&CALC_WSF!$AP$12)) | I55: =IF(OR(CALC_WSF!$B$3="Zone",CALC_WSF!$AP$12=""),"",CALC_WSF!$AQ$12) | J55: =IF(CALC_WSF!$B$3="Zone","",IF(CALC_WSF!$AR$12="","",10&". "&CALC_WSF!$AR$12)) | K55: =IF(OR(CALC_WSF!$B$3="Zone",CALC_WSF!$AR$12=""),"",CALC_WSF!$AS$12) | L55: =IF(CALC_WSF!$B$3="Zone","",IF(CALC_WSF!$AT$12="","",10&". "&CALC_WSF!$AT$12)) | M55: =IF(OR(CALC_WSF!$B$3="Zone",CALC_WSF!$AT$12=""),"",CALC_WSF!$AU$12)
B57: Who didn't report — cells with no WSF return for the selected week
B58: =IF(NOT(CALC_WSF!$AX$2),"Cell-level detail is kept in the workbook for the latest "&8&" weeks only; older weeks are in the archive folder (WSF_cells_YYYY.csv).",TEXT(CALC_WSF!$AX$1,"#,##0")&" cells did not report in this scope"&IF(CALC_WSF!$AX$1>50," — showing the first 50. Narrow with Scope = Area or Zone.",".")&" Zones where no cell reported: "&TEXT(CALC_WSF!$B$17,"#,##0")&".")
B59: Area | E59: Zone | I59: Cell | K59: Week ending
B60: =CALC_WSF!$AX$4 | E60: =CALC_WSF!$AY$4 | I60: =CALC_WSF!$AZ$4 | K60: =IF(CALC_WSF!$AW$4="","",CALC_WSF!$B$10)
...

Sheet MIDWEEK DASHBOARD
B1: MIDWEEK DASHBOARD | N1: ⌂ HOME
B2: Zonal midweek services
B4: Stage 2: this dashboard is built after the WSF DASHBOARD is reviewed, using the same control strip, KPI cards, time analysis, rankings and non-reporting layout. Its data is already loaded in the DATA_MIDWEEK sheet.

Sheet CHOP DASHBOARD
B1: CHOP DASHBOARD | N1: ⌂ HOME
B2: Covenant Hour of Prayer (CHOP zones only)
B4: Stage 2: this dashboard is built after the WSF DASHBOARD is reviewed, using the same control strip, KPI cards, time analysis, rankings and non-reporting layout. Its data is already loaded in the DATA_CHOP sheet.

Sheet COMMUNITY CHURCH DASHBOARD
B1: COMMUNITY CHURCH DASHBOARD | N1: ⌂ HOME
B2: 35 Community Churches · Sunday service first
B4: Stage 2: this dashboard is built after the WSF DASHBOARD is reviewed, using the same control strip, KPI cards, time analysis, rankings and non-reporting layout. Its data is already loaded in the DATA_COMMUNITY sheet.

Sheet TRANSPORT DASHBOARD
B1: TRANSPORT DASHBOARD | N1: ⌂ HOME
B2: FT Procured (hired LT) · church coasters · EV/TATA · WSF Procured (member-paid) · riders, seats, spend and optimisation
B3: SCOPE | C3: SEARCH (type part of a name) | E3: SELECT AREA / ZONE ▼ | H3: STREAM | I3: WEEK ENDING ▼ | K3: COMPARE (WEEKS) | L3: SHOWING
B4: Global | H4: Transport | I4: Latest | K4: 4 | L4: =CALC_TRANSPORT!$B$16&IF(CALC_TRANSPORT!$B$10=0,""," · w/e "&TEXT(CALC_TRANSPORT!$B$10,"dd mmm yyyy"))&" · "&CALC_TRANSPORT!$B$11&"-wk window"
B5: =IF(CALC_TRANSPORT!$B$9=0,"No transport reports loaded yet. Put the weekly transport files in the inbox and run ingest.py.",IF(NOT(CALC_TRANSPORT!$B$5),"⚠ Pick "&IF(CALC_TRANSPORT!$B$3="Area","an Area","a Zone")&" from SELECT (type part of the name in SEARCH first).",IF(CALC_TRANSPORT!$B$3="Zone","Zone scope shows FT Procured and WSF Procured only (coasters, EV/TATA, fuel and budget are by Area).",IF(CALC_TRANSPORT!$X$21=0,"No transport reports in this scope for the selected week.","Utilisation = riders ÷ seats offered, on buses whose capacity is known. Spend = hire cost + coaster fuel paid (hubs only)."))))
B7: RIDERS CARRIED | D7: BUSES THAT RAN | F7: SEAT UTILISATION | H7: TOTAL SPEND | J7: COST PER RIDER | L7: FT SPEND vs BUDGET | N7: BREAKDOWNS
B8: =IF(CALC_TRANSPORT!$B$90="","–",CALC_TRANSPORT!$B$90) | D8: =IF(CALC_TRANSPORT!$B$91="","–",CALC_TRANSPORT!$B$91) | F8: =IF(CALC_TRANSPORT!$B$95="","–",CALC_TRANSPORT!$B$95) | H8: =IF(CALC_TRANSPORT!$B$96="","–",CALC_TRANSPORT!$B$96) | J8: =IF(CALC_TRANSPORT!$B$100="","–",CALC_TRANSPORT!$B$100) | L8: =IF(CALC_TRANSPORT!$B$103="","–",CALC_TRANSPORT!$B$103) | N8: =IF(CALC_TRANSPORT!$B$104="","–",CALC_TRANSPORT!$B$104)
B9: =IF(CALC_TRANSPORT!$E$90="","– vs prev wk",IF(CALC_TRANSPORT!$E$90>=0,"▲ ","▼ ")&TEXT(ABS(CALC_TRANSPORT!$E$90),"0.0%")&" vs prev wk") | D9: =IF(CALC_TRANSPORT!$E$91="","– vs prev wk",IF(CALC_TRANSPORT!$E$91>=0,"▲ ","▼ ")&TEXT(ABS(CALC_TRANSPORT!$E$91),"0.0%")&" vs prev wk") | F9: =IF(CALC_TRANSPORT!$D$95="","– vs prev wk",IF(CALC_TRANSPORT!$D$95>=0,"▲ ","▼ ")&TEXT(ABS(CALC_TRANSPORT!$D$95)*100,"0.0")&" pts vs prev wk") | H9: =IF(CALC_TRANSPORT!$E$96="","– vs prev wk",IF(CALC_TRANSPORT!$E$96>=0,"▲ ","▼ ")&TEXT(ABS(CALC_TRANSPORT!$E$96),"0.0%")&" vs prev wk") | J9: =IF(CALC_TRANSPORT!$E$100="","– vs prev wk",IF(CALC_TRANSPORT!$E$100>=0,"▲ ","▼ ")&TEXT(ABS(CALC_TRANSPORT!$E$100),"0.0%")&" vs prev wk") | L9: =IF(CALC_TRANSPORT!$D$103="","– vs prev wk",IF(CALC_TRANSPORT!$D$103>=0,"▲ ","▼ ")&TEXT(ABS(CALC_TRANSPORT!$D$103)*100,"0.0")&" pts vs prev wk") | N9: =IF(CALC_TRANSPORT!$E$104="","– vs prev wk",IF(CALC_TRANSPORT!$E$104>=0,"▲ ","▼ ")&TEXT(ABS(CALC_TRANSPORT!$E$104),"0.0%")&" vs prev wk")
B10: ="Avg last "&CALC_TRANSPORT!$B$11&" wks: "&IF(CALC_TRANSPORT!$F$90="","–",TEXT(CALC_TRANSPORT!$F$90,"#,##0")) | D10: ="Avg last "&CALC_TRANSPORT!$B$11&" wks: "&IF(CALC_TRANSPORT!$F$91="","–",TEXT(CALC_TRANSPORT!$F$91,"#,##0")) | F10: ="Avg last "&CALC_TRANSPORT!$B$11&" wks: "&IF(CALC_TRANSPORT!$F$95="","–",TEXT(CALC_TRANSPORT!$F$95,"0.0%")) | H10: ="Avg last "&CALC_TRANSPORT!$B$11&" wks: "&IF(CALC_TRANSPORT!$F$96="","–","₦"&TEXT(CALC_TRANSPORT!$F$96,"#,##0")) | J10: ="Avg last "&CALC_TRANSPORT!$B$11&" wks: "&IF(CALC_TRANSPORT!$F$100="","–","₦"&TEXT(CALC_TRANSPORT!$F$100,"#,##0.00")) | L10: ="Avg last "&CALC_TRANSPORT!$B$11&" wks: "&IF(CALC_TRANSPORT!$F$103="","–",TEXT(CALC_TRANSPORT!$F$103,"0.0%")) | N10: ="Avg last "&CALC_TRANSPORT!$B$11&" wks: "&IF(CALC_TRANSPORT!$F$104="","–",TEXT(CALC_TRANSPORT!$F$104,"#,##0"))
B12: By bus category — selected week | O12: Cost per rider shows where money works hardest
B13: Category | D13: Listed | E13: Ran | F13: % ran | G13: Riders | H13: Seats | I13: Utilisation | J13: Spend | K13: Cost / rider | L13: Cost / bus | M13: Cost / seat | N13: Riders WoW | O13: Paid by
B14: =CALC_TRANSPORT!$A$110 | D14: =IF(CALC_TRANSPORT!$B$110="","–",CALC_TRANSPORT!$B$110) | E14: =IF(CALC_TRANSPORT!$C$110="","–",CALC_TRANSPORT!$C$110) | F14: =IF(CALC_TRANSPORT!$D$110="","–",CALC_TRANSPORT!$D$110) | G14: =IF(CALC_TRANSPORT!$E$110="","–",CALC_TRANSPORT!$E$110) | H14: =IF(CALC_TRANSPORT!$F$110="","–",CALC_TRANSPORT!$F$110) | I14: =IF(CALC_TRANSPORT!$H$110="","–",CALC_TRANSPORT!$H$110) | J14: =IF(CALC_TRANSPORT!$K$110="","–",CALC_TRANSPORT!$K$110) | K14: =IF(CALC_TRANSPORT!$L$110="","–",CALC_TRANSPORT!$L$110) | L14: =IF(CALC_TRANSPORT!$M$110="","–",CALC_TRANSPORT!$M$110) | M14: =IF(CALC_TRANSPORT!$N$110="","–",CALC_TRANSPORT!$N$110) | N14: =IF(CALC_TRANSPORT!$P$110="","–",CALC_TRANSPORT!$P$110) | O14: =CALC_TRANSPORT!$Q$110
B15: =CALC_TRANSPORT!$A$111 | D15: =IF(CALC_TRANSPORT!$B$111="","–",CALC_TRANSPORT!$B$111) | E15: =IF(CALC_TRANSPORT!$C$111="","–",CALC_TRANSPORT!$C$111) | F15: =IF(CALC_TRANSPORT!$D$111="","–",CALC_TRANSPORT!$D$111) | G15: =IF(CALC_TRANSPORT!$E$111="","–",CALC_TRANSPORT!$E$111) | H15: =IF(CALC_TRANSPORT!$F$111="","–",CALC_TRANSPORT!$F$111) | I15: =IF(CALC_TRANSPORT!$H$111="","–",CALC_TRANSPORT!$H$111) | J15: =IF(CALC_TRANSPORT!$K$111="","–",CALC_TRANSPORT!$K$111) | K15: =IF(CALC_TRANSPORT!$L$111="","–",CALC_TRANSPORT!$L$111) | L15: =IF(CALC_TRANSPORT!$M$111="","–",CALC_TRANSPORT!$M$111) | M15: =IF(CALC_TRANSPORT!$N$111="","–",CALC_TRANSPORT!$N$111) | N15: =IF(CALC_TRANSPORT!$P$111="","–",CALC_TRANSPORT!$P$111) | O15: =CALC_TRANSPORT!$Q$111
B16: =CALC_TRANSPORT!$A$112 | D16: =IF(CALC_TRANSPORT!$B$112="","–",CALC_TRANSPORT!$B$112) | E16: =IF(CALC_TRANSPORT!$C$112="","–",CALC_TRANSPORT!$C$112) | F16: =IF(CALC_TRANSPORT!$D$112="","–",CALC_TRANSPORT!$D$112) | G16: =IF(CALC_TRANSPORT!$E$112="","–",CALC_TRANSPORT!$E$112) | H16: =IF(CALC_TRANSPORT!$F$112="","–",CALC_TRANSPORT!$F$112) | I16: =IF(CALC_TRANSPORT!$H$112="","–",CALC_TRANSPORT!$H$112) | J16: =IF(CALC_TRANSPORT!$K$112="","–",CALC_TRANSPORT!$K$112) | K16: =IF(CALC_TRANSPORT!$L$112="","–",CALC_TRANSPORT!$L$112) | L16: =IF(CALC_TRANSPORT!$M$112="","–",CALC_TRANSPORT!$M$112) | M16: =IF(CALC_TRANSPORT!$N$112="","–",CALC_TRANSPORT!$N$112) | N16: =IF(CALC_TRANSPORT!$P$112="","–",CALC_TRANSPORT!$P$112) | O16: =CALC_TRANSPORT!$Q$112
B17: =CALC_TRANSPORT!$A$113 | D17: =IF(CALC_TRANSPORT!$B$113="","–",CALC_TRANSPORT!$B$113) | E17: =IF(CALC_TRANSPORT!$C$113="","–",CALC_TRANSPORT!$C$113) | F17: =IF(CALC_TRANSPORT!$D$113="","–",CALC_TRANSPORT!$D$113) | G17: =IF(CALC_TRANSPORT!$E$113="","–",CALC_TRANSPORT!$E$113) | H17: =IF(CALC_TRANSPORT!$F$113="","–",CALC_TRANSPORT!$F$113) | I17: =IF(CALC_TRANSPORT!$H$113="","–",CALC_TRANSPORT!$H$113) | J17: =IF(CALC_TRANSPORT!$K$113="","–",CALC_TRANSPORT!$K$113) | K17: =IF(CALC_TRANSPORT!$L$113="","–",CALC_TRANSPORT!$L$113) | L17: =IF(CALC_TRANSPORT!$M$113="","–",CALC_TRANSPORT!$M$113) | M17: =IF(CALC_TRANSPORT!$N$113="","–",CALC_TRANSPORT!$N$113) | N17: =IF(CALC_TRANSPORT!$P$113="","–",CALC_TRANSPORT!$P$113) | O17: =CALC_TRANSPORT!$Q$113
B18: =CALC_TRANSPORT!$A$114 | D18: =IF(CALC_TRANSPORT!$B$114="","–",CALC_TRANSPORT!$B$114) | E18: =IF(CALC_TRANSPORT!$C$114="","–",CALC_TRANSPORT!$C$114) | F18: =IF(CALC_TRANSPORT!$D$114="","–",CALC_TRANSPORT!$D$114) | G18: =IF(CALC_TRANSPORT!$E$114="","–",CALC_TRANSPORT!$E$114) | H18: =IF(CALC_TRANSPORT!$F$114="","–",CALC_TRANSPORT!$F$114) | I18: =IF(CALC_TRANSPORT!$H$114="","–",CALC_TRANSPORT!$H$114) | J18: =IF(CALC_TRANSPORT!$K$114="","–",CALC_TRANSPORT!$K$114) | K18: =IF(CALC_TRANSPORT!$L$114="","–",CALC_TRANSPORT!$L$114) | L18: =IF(CALC_TRANSPORT!$M$114="","–",CALC_TRANSPORT!$M$114) | M18: =IF(CALC_TRANSPORT!$N$114="","–",CALC_TRANSPORT!$N$114) | N18: =IF(CALC_TRANSPORT!$P$114="","–",CALC_TRANSPORT!$P$114) | O18: =CALC_TRANSPORT!$Q$114
B20: Time analysis — selected week against previous week, the N-week average and period-to-date
B21: KPI | D21: Selected week | E21: Previous week | F21: Change | G21: % change | H21: ="Avg last "&CALC_TRANSPORT!$B$11&" wks" | I21: ="vs "&CALC_TRANSPORT!$B$11&"-wk avg" | J21: MTD total | K21: QTD total | L21: YTD total | M21: Wkly avg (month) | N21: Wkly avg (qtr) | O21: Wkly avg (year)
B22: Riders carried | D22: =IF(CALC_TRANSPORT!$B$90="","–",CALC_TRANSPORT!$B$90) | E22: =IF(CALC_TRANSPORT!$C$90="","–",CALC_TRANSPORT!$C$90) | F22: =IF(CALC_TRANSPORT!$D$90="","–",CALC_TRANSPORT!$D$90) | G22: =IF(CALC_TRANSPORT!$E$90="","–",CALC_TRANSPORT!$E$90) | H22: =IF(CALC_TRANSPORT!$F$90="","–",CALC_TRANSPORT!$F$90) | I22: =IF(CALC_TRANSPORT!$G$90="","–",CALC_TRANSPORT!$G$90) | J22: =IF(CALC_TRANSPORT!$H$90="","–",CALC_TRANSPORT!$H$90) | K22: =IF(CALC_TRANSPORT!$I$90="","–",CALC_TRANSPORT!$I$90) | L22: =IF(CALC_TRANSPORT!$J$90="","–",CALC_TRANSPORT!$J$90) | M22: =IF(CALC_TRANSPORT!$K$90="","–",CALC_TRANSPORT!$K$90) | N22: =IF(CALC_TRANSPORT!$L$90="","–",CALC_TRANSPORT!$L$90) | O22: =IF(CALC_TRANSPORT!$M$90="","–",CALC_TRANSPORT!$M$90)
B23: Buses that ran | D23: =IF(CALC_TRANSPORT!$B$91="","–",CALC_TRANSPORT!$B$91) | E23: =IF(CALC_TRANSPORT!$C$91="","–",CALC_TRANSPORT!$C$91) | F23: =IF(CALC_TRANSPORT!$D$91="","–",CALC_TRANSPORT!$D$91) | G23: =IF(CALC_TRANSPORT!$E$91="","–",CALC_TRANSPORT!$E$91) | H23: =IF(CALC_TRANSPORT!$F$91="","–",CALC_TRANSPORT!$F$91) | I23: =IF(CALC_TRANSPORT!$G$91="","–",CALC_TRANSPORT!$G$91) | J23: =IF(CALC_TRANSPORT!$H$91="","–",CALC_TRANSPORT!$H$91) | K23: =IF(CALC_TRANSPORT!$I$91="","–",CALC_TRANSPORT!$I$91) | L23: =IF(CALC_TRANSPORT!$J$91="","–",CALC_TRANSPORT!$J$91) | M23: =IF(CALC_TRANSPORT!$K$91="","–",CALC_TRANSPORT!$K$91) | N23: =IF(CALC_TRANSPORT!$L$91="","–",CALC_TRANSPORT!$L$91) | O23: =IF(CALC_TRANSPORT!$M$91="","–",CALC_TRANSPORT!$M$91)
B24: Buses listed in reports | D24: =IF(CALC_TRANSPORT!$B$92="","–",CALC_TRANSPORT!$B$92) | E24: =IF(CALC_TRANSPORT!$C$92="","–",CALC_TRANSPORT!$C$92) | F24: =IF(CALC_TRANSPORT!$D$92="","–",CALC_TRANSPORT!$D$92) | G24: =IF(CALC_TRANSPORT!$E$92="","–",CALC_TRANSPORT!$E$92) | H24: =IF(CALC_TRANSPORT!$F$92="","–",CALC_TRANSPORT!$F$92) | I24: =IF(CALC_TRANSPORT!$G$92="","–",CALC_TRANSPORT!$G$92) | J24: =IF(CALC_TRANSPORT!$H$92="","–",CALC_TRANSPORT!$H$92) | K24: =IF(CALC_TRANSPORT!$I$92="","–",CALC_TRANSPORT!$I$92) | L24: =IF(CALC_TRANSPORT!$J$92="","–",CALC_TRANSPORT!$J$92) | M24: =IF(CALC_TRANSPORT!$K$92="","–",CALC_TRANSPORT!$K$92) | N24: =IF(CALC_TRANSPORT!$L$92="","–",CALC_TRANSPORT!$L$92) | O24: =IF(CALC_TRANSPORT!$M$92="","–",CALC_TRANSPORT!$M$92)
B25: % buses that ran | D25: =IF(CALC_TRANSPORT!$B$93="","–",CALC_TRANSPORT!$B$93) | E25: =IF(CALC_TRANSPORT!$C$93="","–",CALC_TRANSPORT!$C$93) | F25: =IF(CALC_TRANSPORT!$D$93="","–",CALC_TRANSPORT!$D$93*100) | G25: =IF(CALC_TRANSPORT!$E$93="","–",CALC_TRANSPORT!$E$93) | H25: =IF(CALC_TRANSPORT!$F$93="","–",CALC_TRANSPORT!$F$93) | I25: =IF(CALC_TRANSPORT!$G$93="","–",CALC_TRANSPORT!$G$93) | J25: =IF(CALC_TRANSPORT!$H$93="","–",CALC_TRANSPORT!$H$93) | K25: =IF(CALC_TRANSPORT!$I$93="","–",CALC_TRANSPORT!$I$93) | L25: =IF(CALC_TRANSPORT!$J$93="","–",CALC_TRANSPORT!$J$93) | M25: =IF(CALC_TRANSPORT!$K$93="","–",CALC_TRANSPORT!$K$93) | N25: =IF(CALC_TRANSPORT!$L$93="","–",CALC_TRANSPORT!$L$93) | O25: =IF(CALC_TRANSPORT!$M$93="","–",CALC_TRANSPORT!$M$93)
B26: Seats offered | D26: =IF(CALC_TRANSPORT!$B$94="","–",CALC_TRANSPORT!$B$94) | E26: =IF(CALC_TRANSPORT!$C$94="","–",CALC_TRANSPORT!$C$94) | F26: =IF(CALC_TRANSPORT!$D$94="","–",CALC_TRANSPORT!$D$94) | G26: =IF(CALC_TRANSPORT!$E$94="","–",CALC_TRANSPORT!$E$94) | H26: =IF(CALC_TRANSPORT!$F$94="","–",CALC_TRANSPORT!$F$94) | I26: =IF(CALC_TRANSPORT!$G$94="","–",CALC_TRANSPORT!$G$94) | J26: =IF(CALC_TRANSPORT!$H$94="","–",CALC_TRANSPORT!$H$94) | K26: =IF(CALC_TRANSPORT!$I$94="","–",CALC_TRANSPORT!$I$94) | L26: =IF(CALC_TRANSPORT!$J$94="","–",CALC_TRANSPORT!$J$94) | M26: =IF(CALC_TRANSPORT!$K$94="","–",CALC_TRANSPORT!$K$94) | N26: =IF(CALC_TRANSPORT!$L$94="","–",CALC_TRANSPORT!$L$94) | O26: =IF(CALC_TRANSPORT!$M$94="","–",CALC_TRANSPORT!$M$94)
B27: Seat utilisation % | D27: =IF(CALC_TRANSPORT!$B$95="","–",CALC_TRANSPORT!$B$95) | E27: =IF(CALC_TRANSPORT!$C$95="","–",CALC_TRANSPORT!$C$95) | F27: =IF(CALC_TRANSPORT!$D$95="","–",CALC_TRANSPORT!$D$95*100) | G27: =IF(CALC_TRANSPORT!$E$95="","–",CALC_TRANSPORT!$E$95) | H27: =IF(CALC_TRANSPORT!$F$95="","–",CALC_TRANSPORT!$F$95) | I27: =IF(CALC_TRANSPORT!$G$95="","–",CALC_TRANSPORT!$G$95) | J27: =IF(CALC_TRANSPORT!$H$95="","–",CALC_TRANSPORT!$H$95) | K27: =IF(CALC_TRANSPORT!$I$95="","–",CALC_TRANSPORT!$I$95) | L27: =IF(CALC_TRANSPORT!$J$95="","–",CALC_TRANSPORT!$J$95) | M27: =IF(CALC_TRANSPORT!$K$95="","–",CALC_TRANSPORT!$K$95) | N27: =IF(CALC_TRANSPORT!$L$95="","–",CALC_TRANSPORT!$L$95) | O27: =IF(CALC_TRANSPORT!$M$95="","–",CALC_TRANSPORT!$M$95)
B28: Total spend | D28: =IF(CALC_TRANSPORT!$B$96="","–",CALC_TRANSPORT!$B$96) | E28: =IF(CALC_TRANSPORT!$C$96="","–",CALC_TRANSPORT!$C$96) | F28: =IF(CALC_TRANSPORT!$D$96="","–",CALC_TRANSPORT!$D$96) | G28: =IF(CALC_TRANSPORT!$E$96="","–",CALC_TRANSPORT!$E$96) | H28: =IF(CALC_TRANSPORT!$F$96="","–",CALC_TRANSPORT!$F$96) | I28: =IF(CALC_TRANSPORT!$G$96="","–",CALC_TRANSPORT!$G$96) | J28: =IF(CALC_TRANSPORT!$H$96="","–",CALC_TRANSPORT!$H$96) | K28: =IF(CALC_TRANSPORT!$I$96="","–",CALC_TRANSPORT!$I$96) | L28: =IF(CALC_TRANSPORT!$J$96="","–",CALC_TRANSPORT!$J$96) | M28: =IF(CALC_TRANSPORT!$K$96="","–",CALC_TRANSPORT!$K$96) | N28: =IF(CALC_TRANSPORT!$L$96="","–",CALC_TRANSPORT!$L$96) | O28: =IF(CALC_TRANSPORT!$M$96="","–",CALC_TRANSPORT!$M$96)
B29: Central spend (FT hire + coaster fuel) | D29: =IF(CALC_TRANSPORT!$B$97="","–",CALC_TRANSPORT!$B$97) | E29: =IF(CALC_TRANSPORT!$C$97="","–",CALC_TRANSPORT!$C$97) | F29: =IF(CALC_TRANSPORT!$D$97="","–",CALC_TRANSPORT!$D$97) | G29: =IF(CALC_TRANSPORT!$E$97="","–",CALC_TRANSPORT!$E$97) | H29: =IF(CALC_TRANSPORT!$F$97="","–",CALC_TRANSPORT!$F$97) | I29: =IF(CALC_TRANSPORT!$G$97="","–",CALC_TRANSPORT!$G$97) | J29: =IF(CALC_TRANSPORT!$H$97="","–",CALC_TRANSPORT!$H$97) | K29: =IF(CALC_TRANSPORT!$I$97="","–",CALC_TRANSPORT!$I$97) | L29: =IF(CALC_TRANSPORT!$J$97="","–",CALC_TRANSPORT!$J$97) | M29: =IF(CALC_TRANSPORT!$K$97="","–",CALC_TRANSPORT!$K$97) | N29: =IF(CALC_TRANSPORT!$L$97="","–",CALC_TRANSPORT!$L$97) | O29: =IF(CALC_TRANSPORT!$M$97="","–",CALC_TRANSPORT!$M$97)
B30: Member-paid (WSF Procured) | D30: =IF(CALC_TRANSPORT!$B$98="","–",CALC_TRANSPORT!$B$98) | E30: =IF(CALC_TRANSPORT!$C$98="","–",CALC_TRANSPORT!$C$98) | F30: =IF(CALC_TRANSPORT!$D$98="","–",CALC_TRANSPORT!$D$98) | G30: =IF(CALC_TRANSPORT!$E$98="","–",CALC_TRANSPORT!$E$98) | H30: =IF(CALC_TRANSPORT!$F$98="","–",CALC_TRANSPORT!$F$98) | I30: =IF(CALC_TRANSPORT!$G$98="","–",CALC_TRANSPORT!$G$98) | J30: =IF(CALC_TRANSPORT!$H$98="","–",CALC_TRANSPORT!$H$98) | K30: =IF(CALC_TRANSPORT!$I$98="","–",CALC_TRANSPORT!$I$98) | L30: =IF(CALC_TRANSPORT!$J$98="","–",CALC_TRANSPORT!$J$98) | M30: =IF(CALC_TRANSPORT!$K$98="","–",CALC_TRANSPORT!$K$98) | N30: =IF(CALC_TRANSPORT!$L$98="","–",CALC_TRANSPORT!$L$98) | O30: =IF(CALC_TRANSPORT!$M$98="","–",CALC_TRANSPORT!$M$98)
B31: Coaster fuel paid (hubs) | D31: =IF(CALC_TRANSPORT!$B$99="","–",CALC_TRANSPORT!$B$99) | E31: =IF(CALC_TRANSPORT!$C$99="","–",CALC_TRANSPORT!$C$99) | F31: =IF(CALC_TRANSPORT!$D$99="","–",CALC_TRANSPORT!$D$99) | G31: =IF(CALC_TRANSPORT!$E$99="","–",CALC_TRANSPORT!$E$99) | H31: =IF(CALC_TRANSPORT!$F$99="","–",CALC_TRANSPORT!$F$99) | I31: =IF(CALC_TRANSPORT!$G$99="","–",CALC_TRANSPORT!$G$99) | J31: =IF(CALC_TRANSPORT!$H$99="","–",CALC_TRANSPORT!$H$99) | K31: =IF(CALC_TRANSPORT!$I$99="","–",CALC_TRANSPORT!$I$99) | L31: =IF(CALC_TRANSPORT!$J$99="","–",CALC_TRANSPORT!$J$99) | M31: =IF(CALC_TRANSPORT!$K$99="","–",CALC_TRANSPORT!$K$99) | N31: =IF(CALC_TRANSPORT!$L$99="","–",CALC_TRANSPORT!$L$99) | O31: =IF(CALC_TRANSPORT!$M$99="","–",CALC_TRANSPORT!$M$99)
B32: Cost per rider | D32: =IF(CALC_TRANSPORT!$B$100="","–",CALC_TRANSPORT!$B$100) | E32: =IF(CALC_TRANSPORT!$C$100="","–",CALC_TRANSPORT!$C$100) | F32: =IF(CALC_TRANSPORT!$D$100="","–",CALC_TRANSPORT!$D$100) | G32: =IF(CALC_TRANSPORT!$E$100="","–",CALC_TRANSPORT!$E$100) | H32: =IF(CALC_TRANSPORT!$F$100="","–",CALC_TRANSPORT!$F$100) | I32: =IF(CALC_TRANSPORT!$G$100="","–",CALC_TRANSPORT!$G$100) | J32: =IF(CALC_TRANSPORT!$H$100="","–",CALC_TRANSPORT!$H$100) | K32: =IF(CALC_TRANSPORT!$I$100="","–",CALC_TRANSPORT!$I$100) | L32: =IF(CALC_TRANSPORT!$J$100="","–",CALC_TRANSPORT!$J$100) | M32: =IF(CALC_TRANSPORT!$K$100="","–",CALC_TRANSPORT!$K$100) | N32: =IF(CALC_TRANSPORT!$L$100="","–",CALC_TRANSPORT!$L$100) | O32: =IF(CALC_TRANSPORT!$M$100="","–",CALC_TRANSPORT!$M$100)
B33: Cost per bus that ran | D33: =IF(CALC_TRANSPORT!$B$101="","–",CALC_TRANSPORT!$B$101) | E33: =IF(CALC_TRANSPORT!$C$101="","–",CALC_TRANSPORT!$C$101) | F33: =IF(CALC_TRANSPORT!$D$101="","–",CALC_TRANSPORT!$D$101) | G33: =IF(CALC_TRANSPORT!$E$101="","–",CALC_TRANSPORT!$E$101) | H33: =IF(CALC_TRANSPORT!$F$101="","–",CALC_TRANSPORT!$F$101) | I33: =IF(CALC_TRANSPORT!$G$101="","–",CALC_TRANSPORT!$G$101) | J33: =IF(CALC_TRANSPORT!$H$101="","–",CALC_TRANSPORT!$H$101) | K33: =IF(CALC_TRANSPORT!$I$101="","–",CALC_TRANSPORT!$I$101) | L33: =IF(CALC_TRANSPORT!$J$101="","–",CALC_TRANSPORT!$J$101) | M33: =IF(CALC_TRANSPORT!$K$101="","–",CALC_TRANSPORT!$K$101) | N33: =IF(CALC_TRANSPORT!$L$101="","–",CALC_TRANSPORT!$L$101) | O33: =IF(CALC_TRANSPORT!$M$101="","–",CALC_TRANSPORT!$M$101)
B34: Cost per seat offered | D34: =IF(CALC_TRANSPORT!$B$102="","–",CALC_TRANSPORT!$B$102) | E34: =IF(CALC_TRANSPORT!$C$102="","–",CALC_TRANSPORT!$C$102) | F34: =IF(CALC_TRANSPORT!$D$102="","–",CALC_TRANSPORT!$D$102) | G34: =IF(CALC_TRANSPORT!$E$102="","–",CALC_TRANSPORT!$E$102) | H34: =IF(CALC_TRANSPORT!$F$102="","–",CALC_TRANSPORT!$F$102) | I34: =IF(CALC_TRANSPORT!$G$102="","–",CALC_TRANSPORT!$G$102) | J34: =IF(CALC_TRANSPORT!$H$102="","–",CALC_TRANSPORT!$H$102) | K34: =IF(CALC_TRANSPORT!$I$102="","–",CALC_TRANSPORT!$I$102) | L34: =IF(CALC_TRANSPORT!$J$102="","–",CALC_TRANSPORT!$J$102) | M34: =IF(CALC_TRANSPORT!$K$102="","–",CALC_TRANSPORT!$K$102) | N34: =IF(CALC_TRANSPORT!$L$102="","–",CALC_TRANSPORT!$L$102) | O34: =IF(CALC_TRANSPORT!$M$102="","–",CALC_TRANSPORT!$M$102)
B35: FT spend vs FT budget | D35: =IF(CALC_TRANSPORT!$B$103="","–",CALC_TRANSPORT!$B$103) | E35: =IF(CALC_TRANSPORT!$C$103="","–",CALC_TRANSPORT!$C$103) | F35: =IF(CALC_TRANSPORT!$D$103="","–",CALC_TRANSPORT!$D$103*100) | G35: =IF(CALC_TRANSPORT!$E$103="","–",CALC_TRANSPORT!$E$103) | H35: =IF(CALC_TRANSPORT!$F$103="","–",CALC_TRANSPORT!$F$103) | I35: =IF(CALC_TRANSPORT!$G$103="","–",CALC_TRANSPORT!$G$103) | J35: =IF(CALC_TRANSPORT!$H$103="","–",CALC_TRANSPORT!$H$103) | K35: =IF(CALC_TRANSPORT!$I$103="","–",CALC_TRANSPORT!$I$103) | L35: =IF(CALC_TRANSPORT!$J$103="","–",CALC_TRANSPORT!$J$103) | M35: =IF(CALC_TRANSPORT!$K$103="","–",CALC_TRANSPORT!$K$103) | N35: =IF(CALC_TRANSPORT!$L$103="","–",CALC_TRANSPORT!$L$103) | O35: =IF(CALC_TRANSPORT!$M$103="","–",CALC_TRANSPORT!$M$103)
B36: Breakdowns | D36: =IF(CALC_TRANSPORT!$B$104="","–",CALC_TRANSPORT!$B$104) | E36: =IF(CALC_TRANSPORT!$C$104="","–",CALC_TRANSPORT!$C$104) | F36: =IF(CALC_TRANSPORT!$D$104="","–",CALC_TRANSPORT!$D$104) | G36: =IF(CALC_TRANSPORT!$E$104="","–",CALC_TRANSPORT!$E$104) | H36: =IF(CALC_TRANSPORT!$F$104="","–",CALC_TRANSPORT!$F$104) | I36: =IF(CALC_TRANSPORT!$G$104="","–",CALC_TRANSPORT!$G$104) | J36: =IF(CALC_TRANSPORT!$H$104="","–",CALC_TRANSPORT!$H$104) | K36: =IF(CALC_TRANSPORT!$I$104="","–",CALC_TRANSPORT!$I$104) | L36: =IF(CALC_TRANSPORT!$J$104="","–",CALC_TRANSPORT!$J$104) | M36: =IF(CALC_TRANSPORT!$K$104="","–",CALC_TRANSPORT!$K$104) | N36: =IF(CALC_TRANSPORT!$L$104="","–",CALC_TRANSPORT!$L$104) | O36: =IF(CALC_TRANSPORT!$M$104="","–",CALC_TRANSPORT!$M$104)
B37: Averages use only weeks that have data. MTD/QTD/YTD run to the selected week; ratio rows show the ratio of the period's totals.
B39: Trends — last 13 weeks
B56: Optimisation — selected week, by Area | O56: Thresholds (UtilLow, UtilHigh, UtilLowWeeks) are on SETTINGS
B57: Demand exceeds seats (fullest) | D57: Lowest utilisation | F57: Highest cost per rider | H57: FT spend over budget | J57: Most riders | L57: Plain-language flags
B58: =IF(CALC_TRANSPORT!$B$3="Zone",IF(0=0,"n/a at Zone scope",""),IF(CALC_TRANSPORT!$BD$3="",IF(0=0,"–",""),1&". "&CALC_TRANSPORT!$BD$3)) | C58: =IF(OR(CALC_TRANSPORT!$B$3="Zone",CALC_TRANSPORT!$BD$3=""),"",CALC_TRANSPORT!$BE$3) | D58: =IF(CALC_TRANSPORT!$B$3="Zone",IF(0=0,"n/a at Zone scope",""),IF(CALC_TRANSPORT!$BF$3="",IF(0=0,"–",""),1&". "&CALC_TRANSPORT!$BF$3)) | E58: =IF(OR(CALC_TRANSPORT!$B$3="Zone",CALC_TRANSPORT!$BF$3=""),"",CALC_TRANSPORT!$BG$3) | F58: =IF(CALC_TRANSPORT!$B$3="Zone",IF(0=0,"n/a at Zone scope",""),IF(CALC_TRANSPORT!$BH$3="",IF(0=0,"–",""),1&". "&CALC_TRANSPORT!$BH$3)) | G58: =IF(OR(CALC_TRANSPORT!$B$3="Zone",CALC_TRANSPORT!$BH$3=""),"",CALC_TRANSPORT!$BI$3) | H58: =IF(CALC_TRANSPORT!$B$3="Zone",IF(0=0,"n/a at Zone scope",""),IF(CALC_TRANSPORT!$BJ$3="",IF(0=0,"–",""),1&". "&CALC_TRANSPORT!$BJ$3)) | I58: =IF(OR(CALC_TRANSPORT!$B$3="Zone",CALC_TRANSPORT!$BJ$3=""),"",CALC_TRANSPORT!$BK$3) | J58: =IF(CALC_TRANSPORT!$B$3="Zone",IF(0=0,"n/a at Zone scope",""),IF(CALC_TRANSPORT!$BL$3="",IF(0=0,"–",""),1&". "&CALC_TRANSPORT!$BL$3)) | K58: =IF(OR(CALC_TRANSPORT!$B$3="Zone",CALC_TRANSPORT!$BL$3=""),"",CALC_TRANSPORT!$BM$3) | L58: =IF(CALC_TRANSPORT!$B$3="Zone",IF(0=0,"n/a at Zone scope",""),IF(CALC_TRANSPORT!$BN$3="",IF(0=0,"No flags this week",""),"• "&CALC_TRANSPORT!$BN$3))
B59: =IF(CALC_TRANSPORT!$B$3="Zone",IF(1=0,"n/a at Zone scope",""),IF(CALC_TRANSPORT!$BD$4="",IF(1=0,"–",""),2&". "&CALC_TRANSPORT!$BD$4)) | C59: =IF(OR(CALC_TRANSPORT!$B$3="Zone",CALC_TRANSPORT!$BD$4=""),"",CALC_TRANSPORT!$BE$4) | D59: =IF(CALC_TRANSPORT!$B$3="Zone",IF(1=0,"n/a at Zone scope",""),IF(CALC_TRANSPORT!$BF$4="",IF(1=0,"–",""),2&". "&CALC_TRANSPORT!$BF$4)) | E59: =IF(OR(CALC_TRANSPORT!$B$3="Zone",CALC_TRANSPORT!$BF$4=""),"",CALC_TRANSPORT!$BG$4) | F59: =IF(CALC_TRANSPORT!$B$3="Zone",IF(1=0,"n/a at Zone scope",""),IF(CALC_TRANSPORT!$BH$4="",IF(1=0,"–",""),2&". "&CALC_TRANSPORT!$BH$4)) | G59: =IF(OR(CALC_TRANSPORT!$B$3="Zone",CALC_TRANSPORT!$BH$4=""),"",CALC_TRANSPORT!$BI$4) | H59: =IF(CALC_TRANSPORT!$B$3="Zone",IF(1=0,"n/a at Zone scope",""),IF(CALC_TRANSPORT!$BJ$4="",IF(1=0,"–",""),2&". "&CALC_TRANSPORT!$BJ$4)) | I59: =IF(OR(CALC_TRANSPORT!$B$3="Zone",CALC_TRANSPORT!$BJ$4=""),"",CALC_TRANSPORT!$BK$4) | J59: =IF(CALC_TRANSPORT!$B$3="Zone",IF(1=0,"n/a at Zone scope",""),IF(CALC_TRANSPORT!$BL$4="",IF(1=0,"–",""),2&". "&CALC_TRANSPORT!$BL$4)) | K59: =IF(OR(CALC_TRANSPORT!$B$3="Zone",CALC_TRANSPORT!$BL$4=""),"",CALC_TRANSPORT!$BM$4) | L59: =IF(CALC_TRANSPORT!$B$3="Zone",IF(1=0,"n/a at Zone scope",""),IF(CALC_TRANSPORT!$BN$4="",IF(1=0,"No flags this week",""),"• "&CALC_TRANSPORT!$BN$4))
B60: =IF(CALC_TRANSPORT!$B$3="Zone",IF(2=0,"n/a at Zone scope",""),IF(CALC_TRANSPORT!$BD$5="",IF(2=0,"–",""),3&". "&CALC_TRANSPORT!$BD$5)) | C60: =IF(OR(CALC_TRANSPORT!$B$3="Zone",CALC_TRANSPORT!$BD$5=""),"",CALC_TRANSPORT!$BE$5) | D60: =IF(CALC_TRANSPORT!$B$3="Zone",IF(2=0,"n/a at Zone scope",""),IF(CALC_TRANSPORT!$BF$5="",IF(2=0,"–",""),3&". "&CALC_TRANSPORT!$BF$5)) | E60: =IF(OR(CALC_TRANSPORT!$B$3="Zone",CALC_TRANSPORT!$BF$5=""),"",CALC_TRANSPORT!$BG$5) | F60: =IF(CALC_TRANSPORT!$B$3="Zone",IF(2=0,"n/a at Zone scope",""),IF(CALC_TRANSPORT!$BH$5="",IF(2=0,"–",""),3&". "&CALC_TRANSPORT!$BH$5)) | G60: =IF(OR(CALC_TRANSPORT!$B$3="Zone",CALC_TRANSPORT!$BH$5=""),"",CALC_TRANSPORT!$BI$5) | H60: =IF(CALC_TRANSPORT!$B$3="Zone",IF(2=0,"n/a at Zone scope",""),IF(CALC_TRANSPORT!$BJ$5="",IF(2=0,"–",""),3&". "&CALC_TRANSPORT!$BJ$5)) | I60: =IF(OR(CALC_TRANSPORT!$B$3="Zone",CALC_TRANSPORT!$BJ$5=""),"",CALC_TRANSPORT!$BK$5) | J60: =IF(CALC_TRANSPORT!$B$3="Zone",IF(2=0,"n/a at Zone scope",""),IF(CALC_TRANSPORT!$BL$5="",IF(2=0,"–",""),3&". "&CALC_TRANSPORT!$BL$5)) | K60: =IF(OR(CALC_TRANSPORT!$B$3="Zone",CALC_TRANSPORT!$BL$5=""),"",CALC_TRANSPORT!$BM$5) | L60: =IF(CALC_TRANSPORT!$B$3="Zone",IF(2=0,"n/a at Zone scope",""),IF(CALC_TRANSPORT!$BN$5="",IF(2=0,"No flags this week",""),"• "&CALC_TRANSPORT!$BN$5))
...

Sheet AREA SCORECARD
B1: AREA SCORECARD | N1: ⌂ HOME
B2: One Area across every stream, with rank among all Areas
B4: Stage 2: this dashboard is built after the WSF DASHBOARD is reviewed, using the same control strip, KPI cards, time analysis, rankings and non-reporting layout. Its data is already loaded in the DATA_* sheet.

Sheet ZONE SCORECARD
B1: ZONE SCORECARD | N1: ⌂ HOME
B2: One Zone across every stream
B4: Stage 2: this dashboard is built after the WSF DASHBOARD is reviewed, using the same control strip, KPI cards, time analysis, rankings and non-reporting layout. Its data is already loaded in the DATA_* sheet.

Sheet DATA QUALITY
B1: DATA QUALITY | I1: ⌂ HOME
B2: Rejected rows, mismatched totals, duplicates, unknown Areas/Zones/Cells and missing weeks. Fix the source file and drop it in the inbox again; a re-sent file replaces the old rows.
B4: Issues by type
B5: Stream | C5: Severity | D5: Issue | E5: Rows
B6: – | C6: – | D6: No issues logged | E6: 0
B8: Stream coverage
B9: Stream | C9: First week | D9: Latest week | E9: Weeks loaded | F9: Rows in workbook
B10: WSF | E10: 0 | F10: 0
B11: MIDWEEK | E11: 0 | F11: 0
B12: CHOP | E12: 0 | F12: 0
B13: COMMUNITY | E13: 0 | F13: 0
B14: TRANSPORT | E14: 0 | F14: 0
B15: TRANSPORT_COSTS | E15: 0 | F15: 0
B16: TRANSPORT_BUDGET | E16: 0 | F16: 0
B18: Missing weeks (no rows at all between a stream's first and latest week)
B19: Stream | C19: Week ending
B20: None — every stream has data for every week in its range.
B23: Issue log (newest first)
B24: Stream | C24: Severity | D24: Issue | E24: Source file | F24: Row | G24: Week ending | H24: Detail | I24: Logged on
B25: No issues logged.

Sheet DATA_WSF
A1: Week_Ending | B1: Report_Date | C1: Area | D1: Zone | E1: Cells_Total | F1: Cells_Reported | G1: Cells_Not_Reported | H1: Male | I1: Female | J1: Adult_Total | K1: Children | L1: Grand_Total | M1: Source_File | N1: Loaded_On
A2: =IF(B2="","",B2+MOD(WeekEndDay-WEEKDAY(B2,2),7)) | G2: =IF(E2="","",E2-F2) | J2: =IF(H2="","",H2+I2) | L2: =IF(H2="","",J2+K2)

Sheet WSF_CELLS_CURRENT
A1: Week_Ending | B1: Report_Date | C1: Area | D1: Zone | E1: Cell | F1: Reported | G1: Male | H1: Female | I1: Adult_Total | J1: Children | K1: Grand_Total | L1: Source_File | M1: Loaded_On | N1: List_Helper
A2: =IF(B2="","",B2+MOD(WeekEndDay-WEEKDAY(B2,2),7)) | I2: =IF(G2="","",G2+H2) | K2: =IF(G2="","",I2+J2) | N2: =IF(AND(F2="N",A2=CALC_WSF!$B$10,OR(CALC_WSF!$B$6="*",C2=CALC_WSF!$B$6),OR(CALC_WSF!$B$7="*",D2=CALC_WSF!$B$7)),ROW(),"")

Sheet DATA_MIDWEEK
A1: Week_Ending | B1: Report_Date | C1: Area | D1: Zone | E1: Male | F1: Female | G1: Adult_Total | H1: Children | I1: Grand_Total | J1: Source_File | K1: Loaded_On
A2: =IF(B2="","",B2+MOD(WeekEndDay-WEEKDAY(B2,2),7)) | G2: =IF(E2="","",E2+F2) | I2: =IF(E2="","",G2+H2)

Sheet DATA_CHOP
A1: Week_Ending | B1: Report_Date | C1: Area | D1: Zone | E1: Male | F1: Female | G1: Adult_Total | H1: Children | I1: Grand_Total | J1: Source_File | K1: Loaded_On
A2: =IF(B2="","",B2+MOD(WeekEndDay-WEEKDAY(B2,2),7)) | G2: =IF(E2="","",E2+F2) | I2: =IF(E2="","",G2+H2)

Sheet DATA_COMMUNITY
A1: Week_Ending | B1: Report_Date | C1: Church | D1: Service_Type | E1: Male | F1: Female | G1: Adult_Total | H1: Children | I1: Grand_Total | J1: Source_File | K1: Loaded_On
A2: =IF(B2="","",B2+MOD(WeekEndDay-WEEKDAY(B2,2),7)) | G2: =IF(E2="","",E2+F2) | I2: =IF(E2="","",G2+H2)

Sheet DATA_TRANSPORT
A1: Week_Ending | B1: Report_Date | C1: Category | D1: Vehicle_Type | E1: Area | F1: Zone_Code | G1: Location | H1: Vehicle_ID | I1: Buses | J1: Capacity | K1: Trips | L1: Seats_Offered | M1: Male | N1: Female | O1: Adult_Total | P1: Children | Q1: Grand_Total | R1: Riders_With_Seats | S1: Cost | T1: Paid_By | U1: Status | V1: Service | W1: Remarks_Category | X1: Remarks | Y1: In_Church | Z1: Source_File | AA1: Loaded_On | AB1: Zone_Key | AC1: Note_Helper
A2: =IF(B2="","",B2+MOD(WeekEndDay-WEEKDAY(B2,2),7)) | L2: =IF(OR(J2="",J2=0),"",IF(U2="Ran",J2*MAX(1,K2),0)) | O2: =IF(M2="","",M2+N2) | Q2: =IF(M2="","",O2+P2) | R2: =IF(L2="","",Q2) | AB2: =IF(F2="","-",F2) | AC2: =IF(AND(A2=CALC_TRANSPORT!$B$10,OR(CALC_TRANSPORT!$B$6="*",E2=CALC_TRANSPORT!$B$6),OR(CALC_TRANSPORT!$B$7="*",F2=CALC_TRANSPORT!$B$7),OR(U2="Breakdown",W2="Extra passengers",ISNUMBER(SEARCH("more bus",X2)))),ROW(),"")

Sheet DATA_TRANSPORT_COSTS
A1: Week_Ending | B1: Report_Date | C1: Category | D1: Area | E1: Vehicle_ID | F1: Cost_Type | G1: Hub_Status | H1: Trips | I1: Litres | J1: Unit_Price | K1: Amount | L1: Payable | M1: Paid_Amount | N1: Paid_By | O1: Source_File | P1: Loaded_On
A2: =IF(B2="","",B2+MOD(WeekEndDay-WEEKDAY(B2,2),7)) | M2: =IF(L2="Y",K2,0)

Sheet DATA_TRANSPORT_BUDGET
A1: Week_Ending | B1: Report_Date | C1: Area_No | D1: Area | E1: Buses_Allocated | F1: Cost_Per_Bus | G1: Expected_Spend | H1: Payable_This_Week | I1: Source_File | J1: Loaded_On
A2: =IF(B2="","",B2+MOD(WeekEndDay-WEEKDAY(B2,2),7)) | G2: =IF(D2="","",E2*F2)

Sheet MASTER_AREAS
A1: Area_ID | B1: Area_Name | C1: Active | D1: Area_No | E1: Aliases
A2: A01 | B2: CANAANLAND 2 | C2: Y | D2: 1 | E2: CANAANLAND 2 (IGE DARAMOLA);CANAAN LAND 2
A3: A02 | B3: IYESI 1 | C3: Y | D3: 2 | E3: IYESI;IYESI1
A4: A03 | B4: OBASANJO | C4: Y | D4: 3
A5: A04 | B5: OJU ORE | C5: Y | D5: 4 | E5: OJUORE
A6: A05 | B6: CAPERNAUM | C6: Y | D6: 5
A7: A06 | B7: NAZARETH | C7: Y | D7: 6 | E7: NAZARATH
A8: A07 | B8: GOWON ESTATE | C8: Y | D8: 7
A9: A08 | B9: BARUWA | C9: Y | D9: 8
A10: A09 | B10: ABORU | C10: Y | D10: 9
A11: A10 | B11: IYANA ISASHI | C11: Y | D11: 10 | E11: IYANA ISHASHI
A12: A11 | B12: WILKY | C12: Y | D12: 11
A13: A12 | B13: PEDRO | C13: Y | D13: 12 | E13: PETRO
A14: A13 | B14: IJAIYE | C14: Y | D14: 13
A15: A14 | B15: OGBA | C15: Y | D15: 14
A16: A15 | B16: YABA | C16: Y | D16: 15
A17: A16 | B17: MUSHIN | C17: Y | D17: 16
A18: A17 | B18: AMUWO | C18: Y | D18: 17 | E18: AMUWO ODOFIN
A19: A18 | B19: AYOBO | C19: Y | D19: 18
A20: A19 | B20: OLAYEMI | C20: Y | D20: 19
A21: A20 | B21: CANDOS | C21: Y | D21: 20
A22: A21 | B22: MAJIYAGBE | C22: Y | D22: 21 | E22: MAJIYAIGBE
A23: A22 | B23: LAFENWA | C23: Y | D23: 22
A24: A23 | B24: PERFECT PEACE | C24: Y | D24: 23
A25: A24 | B25: ANTHONY | C25: Y | D25: 24
A26: A25 | B26: AKUTE | C26: Y | D26: 25
A27: A26 | B27: DENRO | C27: Y | D27: 26
A28: A27 | B28: OLODI APAPA | C28: Y | D28: 27 | E28: 0L0DI APAPA
A29: A28 | B29: PARKLANE APAPA | C29: Y | D29: 28 | E29: PARKLANE, APAPA;APAPA PARKLANE
A30: A29 | B30: ALAGBADO AKINDE | C30: Y | D30: 29
A31: A30 | B31: AIT | C31: Y | D31: 30 | E31: ALT
A32: A31 | B32: AGEGE | C32: Y | D32: 31
A33: A32 | B33: FAGBA | C33: Y | D33: 32
A34: A33 | B34: ATAN 1 | C34: Y | D34: 33 | E34: ATAN;ATAN1
A35: A34 | B35: ADELANS 1 | C35: Y | D35: 34 | E35: ADELANS;ADELANS1
A36: A35 | B36: LUSADA | C36: Y | D36: 35
A37: A36 | B37: IJEGUN IKOTUN | C37: Y | D37: 36
A38: A37 | B38: IGANDO | C38: Y | D38: 37
A39: A38 | B39: IYANA ODO | C39: Y | D39: 38 | E39: IYANA- ODO
A40: A39 | B40: ARIDA | C40: Y | D40: 39
...

Sheet MASTER_ZONES
A1: Zone_ID | B1: Zone_Name | C1: Area_Name | D1: Has_CHOP | E1: Active
A2: LFC0101 | B2: LFC0101 | C2: CANAANLAND 2 | E2: Y
A3: LFC0102 | B3: LFC0102 | C3: CANAANLAND 2 | E3: Y
A4: LFC0103 | B4: LFC0103 | C4: CANAANLAND 2 | E4: Y
A5: LFC0104 | B5: LFC0104 | C5: CANAANLAND 2 | E5: Y
A6: LFC0105 | B6: LFC0105 | C6: CANAANLAND 2 | E6: Y
A7: LFC0106 | B7: LFC0106 | C7: CANAANLAND 2 | E7: Y
A8: LFC0107 | B8: LFC0107 | C8: CANAANLAND 2 | E8: Y
A9: LFC0108 | B9: LFC0108 | C9: CANAANLAND 2 | E9: Y
A10: LFC0109 | B10: LFC0109 | C10: CANAANLAND 2 | E10: Y
A11: LFC0110 | B11: LFC0110 | C11: CANAANLAND 2 | E11: Y
A12: LFC0111 | B12: LFC0111 | C12: CANAANLAND 2 | E12: Y
A13: LFC0112 | B13: LFC0112 | C13: CANAANLAND 2 | E13: Y
... A1165: LFC9215 | B1165: LFC9215 | C1165: ETI-OSA | E1165: Y

Sheet MASTER_CELLS
A1: Cell | B1: Zone_Name | C1: Area_Name | D1: Operational

Sheet MASTER_COMMUNITY
A1: Church_ID | B1: Church_Name | C1: Location | D1: Active

Sheet MASTER_FLEET
A1: Vehicle_ID | B1: Category | C1: Capacity | D1: Owner | E1: Status | F1: Area_Name | G1: Zone_Name | H1: Hired_By_Type

Sheet CALENDAR
A1: Week_Ending | B1: Week_No | C1: Month | D1: Month_Name | E1: Quarter | F1: Year | G1: Year_Month
A2: =DATE(2024,1,1)+MOD(WeekEndDay-WEEKDAY(DATE(2024,1,1),2),7) | B2: =INT((A2-DATE(YEAR(A2),1,1))/7)+1 | C2: =MONTH(A2) | D2: =TEXT(A2,"mmm") | E2: =ROUNDUP(C2/3,0) | F2: =YEAR(A2) | G2: =F2&"-"&TEXT(C2,"00")
A3: =A2+7 | B3: =INT((A3-DATE(YEAR(A3),1,1))/7)+1 | C3: =MONTH(A3) | D3: =TEXT(A3,"mmm") | E3: =ROUNDUP(C3/3,0) | F3: =YEAR(A3) | G3: =F3&"-"&TEXT(C3,"00")
A4: =A3+7 | B4: =INT((A4-DATE(YEAR(A4),1,1))/7)+1 | C4: =MONTH(A4) | D4: =TEXT(A4,"mmm") | E4: =ROUNDUP(C4/3,0) | F4: =YEAR(A4) | G4: =F4&"-"&TEXT(C4,"00")
A5: =A4+7 | B5: =INT((A5-DATE(YEAR(A5),1,1))/7)+1 | C5: =MONTH(A5) | D5: =TEXT(A5,"mmm") | E5: =ROUNDUP(C5/3,0) | F5: =YEAR(A5) | G5: =F5&"-"&TEXT(C5,"00")
A6: =A5+7 | B6: =INT((A6-DATE(YEAR(A6),1,1))/7)+1 | C6: =MONTH(A6) | D6: =TEXT(A6,"mmm") | E6: =ROUNDUP(C6/3,0) | F6: =YEAR(A6) | G6: =F6&"-"&TEXT(C6,"00")
A7: =A6+7 | B7: =INT((A7-DATE(YEAR(A7),1,1))/7)+1 | C7: =MONTH(A7) | D7: =TEXT(A7,"mmm") | E7: =ROUNDUP(C7/3,0) | F7: =YEAR(A7) | G7: =F7&"-"&TEXT(C7,"00")
A8: =A7+7 | B8: =INT((A8-DATE(YEAR(A8),1,1))/7)+1 | C8: =MONTH(A8) | D8: =TEXT(A8,"mmm") | E8: =ROUNDUP(C8/3,0) | F8: =YEAR(A8) | G8: =F8&"-"&TEXT(C8,"00")
A9: =A8+7 | B9: =INT((A9-DATE(YEAR(A9),1,1))/7)+1 | C9: =MONTH(A9) | D9: =TEXT(A9,"mmm") | E9: =ROUNDUP(C9/3,0) | F9: =YEAR(A9) | G9: =F9&"-"&TEXT(C9,"00")
A10: =A9+7 | B10: =INT((A10-DATE(YEAR(A10),1,1))/7)+1 | C10: =MONTH(A10) | D10: =TEXT(A10,"mmm") | E10: =ROUNDUP(C10/3,0) | F10: =YEAR(A10) | G10: =F10&"-"&TEXT(C10,"00")
A11: =A10+7 | B11: =INT((A11-DATE(YEAR(A11),1,1))/7)+1 | C11: =MONTH(A11) | D11: =TEXT(A11,"mmm") | E11: =ROUNDUP(C11/3,0) | F11: =YEAR(A11) | G11: =F11&"-"&TEXT(C11,"00")
A12: =A11+7 | B12: =INT((A12-DATE(YEAR(A12),1,1))/7)+1 | C12: =MONTH(A12) | D12: =TEXT(A12,"mmm") | E12: =ROUNDUP(C12/3,0) | F12: =YEAR(A12) | G12: =F12&"-"&TEXT(C12,"00")
